Workbook
Name Slicer_Gender: #N/A
Name Slicer_Order_Date: #N/A
Name Slicer_Payment_Type: #N/A
Name Slicer_Product_Category: #N/A
Name Slicer_Store_City: #N/A
Name Slicer_Store_City1: #N/A
Name Slicer_Store_type: #N/A

Sheet Customer_Dim
A1: Customer_ID | B1: Name | C1: Age | D1: Gender | E1: City | F1: State | G1: Country | H1: Loyalty_Level
A2: CUST1000 | B2: sheena bonilla | C2: 55 | D2: Male | E2: Donaldton | F2: North Carolina | G2: USA
A3: CUST1001 | B3: Eugene Nelson | C3: 26 | D3: Female | E3: Phillipsmouth | F3: North Dakota | G3: USA | H3: Platinum
A4: CUST1002 | B4: dr. Benjamin Price | C4: 29 | D4: Female | E4: Kylebury | F4: Alabama | G4: USA | H4: Platinum
A5: CUST1003 | B5: jeremy harris | C5: 59 | D5: Female | E5: Thomastown | F5: Ohio | G5: USA | H5: Bronze
A6: CUST1004 | B6: Caroline Collins | C6: 64 | D6: Female | E6: Nicholasshire | F6: California | G6: USA | H6: Silver
A7: CUST1005 | B7: Christine Vaughn | C7: 24 | D7: Male | E7: East Amandamouth | F7: Oregon | G7: USA | H7: Bronze
A8: CUST1006 | B8: Amber Jackson | C8: 29 | D8: Female | E8: Deborahborough | F8: South Dakota | G8: USA | H8: Platinum
A9: CUST1007 | B9: Daniel Boyd | C9: 29 | D9: Female | E9: West Pamelafurt | F9: West Virginia | G9: USA | H9: Bronze
A10: CUST1008 | B10: Melissa Howard | C10: 53 | D10: Female | E10: Maynardton | F10: New Hampshire | G10: USA | H10: Gold
A11: CUST1009 | B11: Ms. Maria Leach | C11: 64 | D11: Male | E11: Melissashire | F11: Pennsylvania | G11: USA | H11: Platinum
A12: CUST1010 | B12: Dominic Page | C12: 53 | D12: Male | E12: Port Michaelburgh | F12: Pennsylvania | G12: USA | H12: Bronze
A13: CUST1011 | B13: Brian Lopez | C13: 28 | D13: Female | E13: East Krista | F13: New York | G13: USA | H13: Gold
A14: CUST1012 | B14: Kenneth Lambert | C14: 55 | D14: Female | E14: North Kathryn | F14: Kansas | G14: USA | H14: Platinum
... A19: CUST1017 | B19: Adam Cruz | C19: 60 | D19: Female | E19: Brandonville | F19: Georgia | G19: USA | H19: Platinum
A20: CUST1018 | B20: Rhonda Moss | C20: 43 | D20: Male | E20: South William | F20: Kansas | G20: USA
A21: CUST1019 | B21: Michael Torres | C21: 46 | D21: Female | E21: Gonzalezfort | F21: New Jersey | G21: USA | H21: Platinum
A22: CUST1020 | B22: Bridget Allen | C22: 59 | D22: Male | E22: Lake Shaneburgh | F22: Delaware | G22: USA | H22: Silver
A23: CUST1021 | B23: Jeff Martinez | C23: 36 | D23: Female | E23: Smithburgh | F23: Oklahoma | G23: USA | H23: Gold
A24: CUST1022 | B24: paul fox | C24: 33 | D24: Female | E24: Michaelton | F24: Hawaii | G24: USA | H24: Silver
A25: CUST1023 | B25: Jonathan Steele | C25: 52 | D25: Female | E25: Molinabury | F25: Oregon | G25: USA | H25: Silver
A26: CUST1024 | B26: Heather Collins | C26: 40 | D26: Male | E26: Rogerschester | F26: Idaho | G26: USA | H26: Platinum
A27: CUST1025 | B27: Diana Taylor | C27: 59 | D27: Female | E27: Vasqueztown | F27: California | G27: USA | H27: Bronze
A28: CUST1026 | B28: Amber Carlson | C28: 18 | D28: Female | E28: East Michellemouth | F28: Missouri | G28: USA | H28: Gold
A29: CUST1027 | B29: Leslie Johnson | C29: 31 | D29: Male | E29: Mollyshire | F29: Utah | G29: USA
A30: CUST1028 | B30: Joshua Ryan | C30: 27 | D30: Female | E30: New David | F30: New Jersey | G30: USA | H30: Platinum
A31: CUST1029 | B31: David Arnold | C31: 54 | D31: Female | E31: East Jennifer | F31: California | G31: USA | H31: Silver
A32: CUST1030 | B32: Jessica Acevedo | C32: 64 | D32: Female | E32: Amybury | F32: Pennsylvania | G32: USA | H32: Bronze
A33: CUST1031 | B33: Sarah Vance | C33: 41 | D33: Male | E33: Johnsonville | F33: Oregon | G33: USA | H33: Silver
A34: CUST1032 | B34: Mike Jennings | C34: 48 | D34: Female | E34: Fostermouth | F34: Arizona | G34: USA | H34: Gold
A35: CUST1033 | B35: Robert Jones DDS | C35: 25 | D35: Male | E35: Tristanton | F35: Oklahoma | G35: USA | H35: Platinum
A36: CUST1034 | B36: Christopher Olson | C36: 27 | D36: Female | E36: West Richard | F36: Maryland | G36: USA | H36: Platinum
A37: CUST1035 | B37: Rachel Myers | C37: 52 | D37: Male | E37: Robertberg | F37: North Dakota | G37: USA | H37: Silver
A38: CUST1036 | B38: Thomas Phillips | C38: 20 | D38: Female | E38: Luisfurt | F38: Georgia | G38: USA | H38: Gold
A39: CUST1037 | B39: Christopher Carter | C39: 27 | D39: Female | E39: Brendastad | F39: South Dakota | G39: USA
A40: CUST1038 | B40: Deanna Simpson | C40: 35 | D40: Female | E40: Brownport | F40: North Dakota | G40: USA | H40: Bronze
A41: CUST1039 | B41: Tonya Reynolds | C41: 55 | D41: Female | E41: Darleneton | F41: Michigan | G41: USA | H41: Gold
A42: CUST1040 | B42: Eric Vega | C42: 50 | D42: Male | E42: Williamsonland | F42: Kansas | G42: USA | H42: Gold
A43: CUST1041 | B43: James Gibbs | C43: 21 | D43: Male | E43: Mooneyshire | F43: Alaska | G43: USA | H43: Platinum
A44: CUST1042 | B44: William Martin | C44: 19 | D44: Male | E44: Ryanburgh | F44: Connecticut | G44: USA | H44: Platinum
...

Sheet Cleaned Customer_Dim
A1: Customer_ID | B1: Name | C1: Age | D1: Gender | E1: City | F1: State | G1: Country | H1: Loyalty_Level.1
A2: CUST1000 | B2: Sheena Bonilla | C2: 55 | D2: Male | E2: Donaldton | F2: North Carolina | G2: USA | H2: Unknown
A3: CUST1001 | B3: Eugene Nelson | C3: 26 | D3: Female | E3: Phillipsmouth | F3: North Dakota | G3: USA | H3: Platinum
A4: CUST1002 | B4: Dr. Benjamin Price | C4: 29 | D4: Female | E4: Kylebury | F4: Alabama | G4: USA | H4: Platinum
A5: CUST1003 | B5: Jeremy Harris | C5: 59 | D5: Female | E5: Thomastown | F5: Ohio | G5: USA | H5: Bronze
A6: CUST1004 | B6: Caroline Collins | C6: 64 | D6: Female | E6: Nicholasshire | F6: California | G6: USA | H6: Silver
A7: CUST1005 | B7: Christine Vaughn | C7: 24 | D7: Male | E7: East Amandamouth | F7: Oregon | G7: USA | H7: Bronze
A8: CUST1006 | B8: Amber Jackson | C8: 29 | D8: Female | E8: Deborahborough | F8: South Dakota | G8: USA | H8: Platinum
A9: CUST1007 | B9: Daniel Boyd | C9: 29 | D9: Female | E9: West Pamelafurt | F9: West Virginia | G9: USA | H9: Bronze
A10: CUST1008 | B10: Melissa Howard | C10: 53 | D10: Female | E10: Maynardton | F10: New Hampshire | G10: USA | H10: Gold
A11: CUST1009 | B11: Ms. Maria Leach | C11: 64 | D11: Male | E11: Melissashire | F11: Pennsylvania | G11: USA | H11: Platinum
A12: CUST1010 | B12: Dominic Page | C12: 53 | D12: Male | E12: Port Michaelburgh | F12: Pennsylvania | G12: USA | H12: Bronze
A13: CUST1011 | B13: Brian Lopez | C13: 28 | D13: Female | E13: East Krista | F13: New York | G13: USA | H13: Gold
... A501: CUST1499 | B501: Philip Pennington | C501: 27 | D501: Female | E501: East Valerieview | F501: Oregon | G501: USA | H501: Platinum

Sheet Product_Dim
A1: Product_ID | B1: Product_Name | C1: Category | D1: Sub_Category | E1: Brand | F1: Cost | G1: Stock
A2: PROD0 | B2: Brother Laser Printer | C2: Electronics | D2: Computer | E2: Hunt Inc | F2: 112.42 | G2: 416
A3: PROD1 | B3: Men's Graphic T-Shirt | C3: Clothing | D3: Tops | E3: Terry-Moore | F3: 342.56 | G3: 181
A4: PROD2 | B4: Women's Casual Hoodie | C4: Clothing | D4: Outerwear | E4: Sims Inc | G4: 352
A5: P-3 | B5: Men's Running Jacket | C5: Clothing | D5: Outerwear | E5: Pineda Ltd | F5: 364.67 | G5: 452
A6: PROD4 | B6: Women's Yoga Pants | C6: Clothing | D6: Bottoms | E6: Gonzales-Davis | F6: 306.46 | G6: 487
A7: PROD5 | B7: Men's Leather Belt | C7: Clothing | D7: Accessories | E7: Baldwin, Garza and Gonzalez | F7: 261 | G7: 59
A8: PROD6 | B8: Herbal Face Moisturizer | C8: Beauty | D8: Skincare | E8: Davidson PLC | F8: 312.8 | G8: 350
A9: PROD7 | B9: LED Table Lamp | C9: Home | D9: Lighting | E9: Harrell LLC | F9: 218.86 | G9: 170
A10: PROD8 | B10: Wireless Bluetooth Earbuds | C10: Electronics | D10: Audio | E10: Perez-Johnston | F10: 439.07 | G10: 142
A11: PROD9 | B11: Adjustable Dumbbell Set | C11: Sports | D11: Fitness | E11: Hill PLC | F11: 495.72 | G11: 323
A12: PROD10 | B12: Ceramic Kitchen Bowl Set | C12: Home | D12: Kitchen | E12: Hamilton Group | F12: 298.86 | G12: 308
A13: PROD11 | B13: HD Smart TV Stick | C13: Electronics | D13: Accessories | E13: Gibson, Hobbs and Weaver | F13: 449.4
A14: PROD12 | B14: Hair Strengthening Shampoo | C14: Beauty | D14: Haircare | E14: Rice LLC | F14: 115.82 | G14: 460
A15: PROD13 | B15: USB-C Fast Charger | C15: Electronics | D15: Accessories | E15: Dawson-Perkins | F15: 242.23 | G15: 453
A16: PROD14 | B16: Decorative Wall Mirror | C16: Home | D16: Decor | E16: Luna, Anderson and Bowman | F16: 48.01 | G16: 439
A17: PROD15 | B17: 4K Home Projector | C17: Electronics | D17: Appliances | E17: Thomas LLC | F17: 465.34 | G17: 301
A18: P-16 | B18: Beard Grooming Kit | C18: Beauty | D18: Grooming | E18: Erickson-Green | F18: 337.42 | G18: 256
A19: PROD17 | B19: Soccer Training Cone Set | C19: Sports | D19: Accessories | E19: Ford, Murphy and Wilson | F19: 144.53 | G19: 367
A20: PROD18 | B20: Women's Denim Jeans | C20: Clothing | D20: Bottoms | E20: Guerra-Hendrix | G20: 343
A21: PROD19 | B21: Knee Support Brace | C21: Sports | D21: Equipment | E21: May-Reese | F21: 21.34 | G21: 65
A22: PROD20 | B22: Outdoor Sports Water Bottle | C22: Sports | D22: Accessories | E22: Soto-Ellis | F22: 131.51
A23: PROD21 | B23: Multi-Purpose Storage Box | C23: Home | D23: Storage | E23: Gardner-Montes | F23: 123.46 | G23: 76
A24: PROD22 | B24: Carbon Fiber Tennis Racket | C24: Sports | D24: Equipment | E24: Flores, Pineda and Rodriguez | F24: 484.62 | G24: 432
A25: PROD23 | B25: Men's Formal Shirt | C25: Clothing | D25: Tops | E25: Moon, Mora and Santos | G25: 360
A26: PROD24 | B26: Foldable Camping Chair | C26: Sports | D26: Outdoor | E26: Cook Ltd | F26: 166.06 | G26: 340
A27: PROD25 | B27: Women's Scarf Set | C27: Clothing | D27: Accessories | E27: Brown and Sons | F27: 174.02 | G27: 268
A28: PROD26 | B28: Wireless Bluetooth Speaker | C28: Electronics | D28: Audio | E28: Reed-Schmidt | F28: 322.41 | G28: 213
A29: PROD27 | B29: Decorative Floor Vase | C29: Home | D29: Decor | E29: Khan, Jones and Paul | G29: 378
A30: PROD28 | B30: Sports Stopwatch Timer | C30: Sports | D30: Accessories | E30: Burns-Hansen | F30: 38.76 | G30: 137
A31: PROD29 | B31: Fabric Sofa Throw Blanket | C31: Home | D31: Decor | E31: Hoffman Group | F31: 218.48 | G31: 276
A32: PROD30 | B32: Stainless Steel Cutlery Set | C32: Home | D32: Kitchen | E32: Stevens, Fernandez and Martin | F32: 19.52 | G32: 57
A33: PROD31 | B33: Basketball | C33: Sports | D33: Team Sports | E33: Nolan-Snow | F33: 204.39 | G33: 281
A34: PROD32 | B34: Vitamin C Face Serum | C34: Beauty | D34: Skincare | E34: Griffin Ltd | F34: 283.83 | G34: 244
A35: PROD33 | B35: Modern Wall Clock | C35: Home | D35: Decor | E35: Weiss-Watson | F35: 179.77 | G35: 305
A36: PROD34 | B36: Gaming Mechanical Keyboard | C36: Electronics | D36: Computer | E36: Lucero LLC | F36: 419.28 | G36: 86
A37: PROD35 | B37: Bedroom Table Lamp | C37: Home | D37: Lighting | E37: Jones LLC | F37: 382.22 | G37: 329
A38: PROD36 | B38: Women's Summer Dress | C38: Clothing | D38: Tops | E38: Smith-Mills | F38: 223.43 | G38: 154
A39: PROD37 | B39: Men's Casual Sneakers | C39: Clothing | D39: Footwear | E39: Hogan-Lee | F39: 353.47 | G39: 214
A40: PROD38 | B40: Sports Water Hydration Pack | C40: Sports | D40: Outdoor | E40: Sims-Smith | F40: 135.61 | G40: 394
...

Sheet Cleaned Product Dim Dataset
A1: Product_ID | B1: Product_Name | C1: Category | D1: Sub_Category | E1: Brand | F1: Cost | G1: Stock
A2: PROD0 | B2: Brother Laser Printer | C2: Electronics | D2: Computer | E2: Hunt Inc | F2: 113 | G2: 416
A3: PROD1 | B3: Men's Graphic T-Shirt | C3: Clothing | D3: Tops | E3: Terry-Moore | F3: 343 | G3: 181
A4: PROD2 | B4: Women's Casual Hoodie | C4: Clothing | D4: Outerwear | E4: Sims Inc | F4: 255 | G4: 352
A5: PROD3 | B5: Men's Running Jacket | C5: Clothing | D5: Outerwear | E5: Pineda Ltd | F5: 365 | G5: 452
A6: PROD4 | B6: Women's Yoga Pants | C6: Clothing | D6: Bottoms | E6: Gonzales-Davis | F6: 307 | G6: 487
A7: PROD5 | B7: Men's Leather Belt | C7: Clothing | D7: Accessories | E7: Baldwin, Garza and Gonzalez | F7: 261 | G7: 59
A8: PROD6 | B8: Herbal Face Moisturizer | C8: Beauty | D8: Skincare | E8: Davidson PLC | F8: 313 | G8: 350
A9: PROD7 | B9: LED Table Lamp | C9: Home | D9: Lighting | E9: Harrell LLC | F9: 219 | G9: 170
A10: PROD8 | B10: Wireless Bluetooth Earbuds | C10: Electronics | D10: Audio | E10: Perez-Johnston | F10: 440 | G10: 142
A11: PROD9 | B11: Adjustable Dumbbell Set | C11: Sports | D11: Fitness | E11: Hill PLC | F11: 496 | G11: 323
A12: PROD10 | B12: Ceramic Kitchen Bowl Set | C12: Home | D12: Kitchen | E12: Hamilton Group | F12: 299 | G12: 308
A13: PROD11 | B13: HD Smart TV Stick | C13: Electronics | D13: Accessories | E13: Gibson, Hobbs and Weaver | F13: 450 | G13: 274
... A101: PROD99 | B101: Stainless Steel Cookware Set | C101: Home | D101: Kitchen | E101: Campbell Ltd | F101: 202 | G101: 146

Sheet Store_Dim
A1: Store_ID | B1: Store_Name | C1: Region | D1: City | E1: Store_Type
A2: STORE0 | B2: Rivera-Warner | C2: East | D2: Washingtonfurt | E2: Flagship
A3: STORE1 | B3: Martinez, Adkins and Johnson | C3: North | D3: Danielmouth | E3: Flagship
A4: STORE2 | B4: Black-Horn | C4: South | D4: North Nancyview | E4: Outlet
A5: STORE3 | B5: Johnson-Wright | C5: North | D5: Hoodberg | E5: Outlet
A6: STORE4 | B6: Alexander Group | C6: South | D6: Port Sharon | E6: Online
A7: STORE5 | B7: Gray Ltd | C7: North | D7: New Michaelchester | E7: Outlet
A8: STORE6 | B8: Benson-Elliott | C8: East | D8: Port Josephberg | E8: Online
A9: STORE7 | B9: Martinez-Mullins | C9: South | D9: Williamsfurt | E9: Online
A10: STORE8 | B10: Bean, Jones and Park | C10: West | D10: Thompsonborough | E10: Online
A11: STORE9 | B11: Moore, Padilla and Butler | C11: South | D11: East Johnstad | E11: Flagship
A12: STORE10 | B12: Hill, Wagner and Ballard | C12: East | D12: East Davidville | E12: Online
... A21: STORE19 | B21: Mann-Austin | C21: East | D21: Vasquezborough | E21: Online

Sheet Cleaned Stoer_ Dim
A1: Store_ID | B1: Store_Name | C1: Region | D1: City | E1: Store_Type
A2: STORE0 | B2: Rivera-Warner | C2: East | D2: Washingtonfurt | E2: Flagship
A3: STORE1 | B3: Martinez, Adkins and Johnson | C3: North | D3: Danielmouth | E3: Flagship
A4: STORE2 | B4: Black-Horn | C4: South | D4: North Nancyview | E4: Outlet
A5: STORE3 | B5: Johnson-Wright | C5: North | D5: Hoodberg | E5: Outlet
A6: STORE4 | B6: Alexander Group | C6: South | D6: Port Sharon | E6: Online
A7: STORE5 | B7: Gray Ltd | C7: North | D7: New Michaelchester | E7: Outlet
A8: STORE6 | B8: Benson-Elliott | C8: East | D8: Port Josephberg | E8: Online
A9: STORE7 | B9: Martinez-Mullins | C9: South | D9: Williamsfurt | E9: Online
A10: STORE8 | B10: Bean, Jones and Park | C10: West | D10: Thompsonborough | E10: Online
A11: STORE9 | B11: Moore, Padilla and Butler | C11: South | D11: East Johnstad | E11: Flagship
A12: STORE10 | B12: Hill, Wagner and Ballard | C12: East | D12: East Davidville | E12: Online
... A21: STORE19 | B21: Mann-Austin | C21: East | D21: Vasquezborough | E21: Online

Sheet Sales_Fact
A1: Sales_ID | B1: Order_Date | C1: Customer_ID | D1: Product_ID | E1: Store_ID | F1: Quantity | G1: Unit_Price | H1: Discount | I1: Payment_Type | J1: Total_Amount
A2: SALE0 | B2: 45480 | C2: CUST1409 | D2: PROD97 | E2: STORE3 | F2: 1 | G2: 218.04 | H2: 0.09 | I2: Credit Card | J2: 198.4164
A3: SALE1 | B3: 45285 | C3: CUST1467 | D3: PROD74 | E3: STORE17 | F3: 3 | G3: 104.47 | H3: 0.27 | I3: PayPal | J3: 228.7893
A4: SALE2 | B4: 45446 | C4: CUST1056 | D4: PROD49 | E4: STORE8 | F4: 4 | G4: 914.05 | H4: 0.25 | I4: Credit Card | J4: 2742.15
A5: SALE3 | B5: 45259 | C5: CUST1346 | D5: PROD76 | E5: STORE8 | F5: 1 | G5: 921.51 | H5: 0.16 | I5: COD | J5: 774.0684
A6: SALE4 | B6: 45297 | C6: CUST1493 | D6: PROD59 | E6: STORE5 | F6: 3 | G6: 745.3 | H6: 0.18 | I6: Credit Card | J6: 1833.438
A7: SALE5 | B7: 45499 | C7: CUST1116 | D7: PROD15 | E7: STORE7 | F7: 3 | G7: 147.01 | H7: 0.19 | I7: COD | J7: 357.2343
A8: SALE6 | B8: 45850 | C8: CUST1016 | D8: PROD56 | E8: STORE4 | F8: 2 | G8: 785.31 | H8: 0.15 | I8: PayPal | J8: 1335.027
A9: SALE7 | B9: 45248 | C9: CUST1152 | D9: PROD70 | E9: STORE8 | F9: 4 | G9: 342.39 | H9: 0.23 | I9: PayPal | J9: 1054.5612
A10: SALE8 | B10: 45781 | C10: CUST1187 | D10: PROD99 | E10: STORE5 | G10: 448.25 | H10: 0.07 | I10: PayPal | J10: 1250.6175
A11: SALE9 | B11: 45869 | C11: CUST1464 | D11: PROD33 | E11: STORE0 | F11: 2 | G11: 873.17 | H11: 0.23 | I11: PayPal | J11: 1344.6818
A12: SALE10 | B12: 45335 | C12: CUST1065 | D12: PROD24 | E12: STORE14 | F12: 1 | G12: 278.63 | H12: 0.07 | I12: Credit Card | J12: 259.1259
A13: SALE11 | B13: 45801 | C13: CUST1320 | D13: PROD39 | E13: STORE1 | F13: 4 | G13: 286.92 | H13: 0.17 | I13: Credit Card | J13: 952.5744
A14: SALE12 | B14: 45528 | C14: CUST1237 | D14: PROD88 | E14: STORE4 | F14: 4 | G14: 644.58 | H14: 0.01 | I14: Credit Card | J14: 2552.5368
A15: SALE13 | B15: 45875 | C15: CUST1443 | D15: PROD34 | E15: STORE16 | F15: 2 | G15: 316.9 | H15: 0.3 | I15: PayPal | J15: 443.66
A16: SALE14 | B16: 45829 | C16: CUST1348 | D16: PROD24 | E16: STORE15 | F16: 4 | G16: 403.47 | H16: 0.29 | I16: PayPal | J16: 1145.8548
A17: SALE15 | B17: 45636 | C17: CUST1435 | D17: PROD36 | E17: STORE9 | G17: 871.34 | H17: 0.04 | I17: COD | J17: 2509.4592
A18: SALE16 | B18: 45913 | C18: CUST1276 | D18: PROD65 | E18: STORE19 | F18: 2 | G18: 451.98 | H18: 0.25 | I18: Credit Card | J18: 677.97
A19: SALE17 | B19: 45637 | C19: CUST1079 | D19: PROD27 | E19: STORE4 | F19: 2 | G19: 502.69 | H19: 0.23 | I19: Credit Card | J19: 774.1426
A20: SALE18 | B20: 45517 | C20: CUST1094 | D20: PROD39 | E20: STORE4 | F20: 2 | G20: 559.23 | H20: 0.25 | I20: COD | J20: 838.845
A21: SALE19 | B21: 45369 | C21: CUST1239 | D21: PROD60 | E21: STORE13 | F21: 4 | H21: 0.04 | I21: COD | J21: 1782.4512
A22: SALE20 | B22: 45843 | C22: CUST1144 | D22: PROD72 | E22: STORE17 | F22: 3 | G22: 986.04 | H22: 0.27 | I22: COD | J22: 2159.4276
A23: SALE21 | B23: 45447 | C23: CUST1396 | D23: PROD43 | E23: STORE18 | F23: 1 | G23: 589.56 | H23: 0.22 | I23: Credit Card | J23: 459.8568
A24: SALE22 | B24: 45394 | C24: CUST1476 | D24: PROD69 | E24: STORE10 | F24: 3 | G24: 979.42 | H24: 0.03 | I24: PayPal | J24: 2850.1122
A25: SALE23 | B25: 45466 | C25: CUST1368 | D25: PROD12 | E25: STORE8 | F25: 1 | G25: 719.28 | H25: 0.08 | I25: Credit Card | J25: 661.7376
A26: SALE24 | B26: 45908 | C26: CUST1186 | D26: PROD67 | E26: STORE6 | F26: 3 | G26: 77.6 | H26: 0.07 | I26: Credit Card | J26: 216.504
A27: SALE25 | B27: 45552 | C27: CUST1381 | D27: PROD5 | E27: STORE3 | F27: 4 | G27: 852.71 | H27: 0.14 | I27: PayPal | J27: 2933.3224
A28: SALE26 | B28: 45294 | C28: CUST1213 | D28: PROD98 | E28: STORE8 | F28: 4 | G28: 156.16 | I28: Credit Card | J28: 599.6544
A29: SALE27 | B29: 45710 | C29: CUST1200 | D29: PROD77 | E29: STORE8 | F29: 3 | G29: 815.49 | H29: 0.17 | I29: Credit Card | J29: 2030.5701
A30: SALE28 | B30: 45923 | C30: CUST1148 | D30: PROD13 | E30: STORE2 | F30: 2 | G30: 74.21 | H30: 0.11 | I30: PayPal | J30: 132.0938
A31: SALE29 | B31: 45302 | C31: CUST1348 | D31: PROD99 | E31: STORE3 | G31: 451.67 | H31: 0.15 | I31: Credit Card | J31: 1535.678
A32: SALE30 | B32: 45217 | C32: CUST1028 | D32: PROD5 | E32: STORE19 | F32: 1 | G32: 429.38 | H32: 0.13 | I32: PayPal | J32: 373.5606
A33: SALE31 | B33: 45593 | C33: CUST1412 | D33: PROD53 | E33: STORE12 | F33: 2 | G33: 148.96 | H33: 0.03 | I33: COD | J33: 288.9824
A34: SALE32 | B34: 45597 | C34: CUST1398 | D34: PROD75 | E34: STORE8 | F34: 4 | G34: 313.83 | H34: 0.08 | I34: Credit Card | J34: 1154.8944
A35: SALE33 | B35: 45620 | C35: CUST1453 | D35: PROD12 | E35: STORE6 | F35: 2 | G35: 717.31 | H35: 0.15 | I35: Credit Card | J35: 1219.427
A36: SALE34 | B36: 45215 | C36: CUST1344 | D36: PROD79 | E36: STORE1 | G36: 873.22 | H36: 0.18 | I36: Credit Card | J36: 2148.1212
A37: SALE35 | B37: 45878 | C37: CUST1218 | D37: PROD16 | E37: STORE3 | F37: 4 | G37: 109.36 | H37: 0.19 | I37: COD | J37: 354.3264
A38: SALE36 | B38: 45635 | C38: CUST1086 | D38: PROD5 | E38: STORE7 | F38: 3 | G38: 559.52 | H38: 0.16 | I38: PayPal | J38: 1409.9904
A39: SALE37 | B39: 45329 | C39: CUST1492 | D39: PROD10 | E39: STORE17 | F39: 3 | G39: 121.76 | H39: 0.27 | I39: PayPal | J39: 266.6544
A40: SALE38 | B40: 45378 | C40: CUST1189 | D40: PROD33 | E40: STORE13 | F40: 4 | G40: 735.32 | H40: 0.06 | I40: COD | J40: 2764.8032
...

Sheet Cleaned Sales Fact 
A1: Sales_ID | B1: Order_Date | C1: Customer_ID | D1: Product_ID | E1: Store_ID | F1: Quantity | G1: Unit_Price | H1: Discount | I1: Payment_Type | J1: Total_Amount | K1: Gender | L1: Customer State | M1: Store name | N1: Store Region | O1: Store City | P1: Store type | Q1: Product Name | R1: Product Category | S1: Product Sub Category | T1: Product Brands
A2: SALE0 | B2: 45480 | C2: CUST1409 | D2: PROD97 | E2: STORE3 | F2: 1 | G2: 218.04 | H2: 0.09 | I2: Credit Card | J2: 198.42 | K2: =VLOOKUP(C2,'Cleaned Customer_Dim'!$A$2:$H$501,4,0) -> Male | L2: =VLOOKUP(C2, 'Cleaned Customer_Dim'!$A:$F, 6, FALSE) -> Wyoming | M2: =VLOOKUP(E2, 'Cleaned Stoer_ Dim'!$A$1:$E$21, 2, 0) -> Johnson-Wright | N2: =VLOOKUP(E2, 'Cleaned Stoer_ Dim'!$A:$E,3, 0) -> North | O2: =VLOOKUP(E2, 'Cleaned Stoer_ Dim'!$A:$E, 4, 0) -> Hoodberg | P2: =VLOOKUP(E2, 'Cleaned Stoer_ Dim'!$A:$E, 5, 0) -> Outlet | Q2: =VLOOKUP(D2, 'Cleaned Product Dim Dataset'!$A:$G, 2, 0) -> Cricket Bat | R2: =VLOOKUP(D2, 'Cleaned Product Dim Dataset'!$A:$G, 3, 0) -> Sports | S2: =VLOOKUP(D2, 'Cleaned Product Dim Dataset'!$A:$G, 4, 0) -> Team Sports | T2: =VLOOKUP(D2, 'Cleaned Product Dim Dataset'!$A:$G, 5, 0) -> Khan LLC
A3: SALE1 | B3: 45285 | C3: CUST1467 | D3: PROD74 | E3: STORE17 | F3: 3 | G3: 104.47 | H3: 0.27 | I3: PayPal | J3: 228.79 | K3: =VLOOKUP(C3,'Cleaned Customer_Dim'!$A$2:$H$501,4,0) -> Female | L3: =VLOOKUP(C3, 'Cleaned Customer_Dim'!$A:$F, 6, FALSE) -> Vermont | M3: =VLOOKUP(E3, 'Cleaned Stoer_ Dim'!$A$1:$E$21, 2, 0) -> Holloway Ltd | N3: =VLOOKUP(E3, 'Cleaned Stoer_ Dim'!$A:$E,3, 0) -> North | O3: =VLOOKUP(E3, 'Cleaned Stoer_ Dim'!$A:$E, 4, 0) -> Bensonhaven | P3: =VLOOKUP(E3, 'Cleaned Stoer_ Dim'!$A:$E, 5, 0) -> Flagship | Q3: =VLOOKUP(D3, 'Cleaned Product Dim Dataset'!$A:$G, 2, 0) -> Bluetooth Car Audio System | R3: =VLOOKUP(D3, 'Cleaned Product Dim Dataset'!$A:$G, 3, 0) -> Electronics | S3: =VLOOKUP(D3, 'Cleaned Product Dim Dataset'!$A:$G, 4, 0) -> Audio | T3: =VLOOKUP(D3, 'Cleaned Product Dim Dataset'!$A:$G, 5, 0) -> Bruce-Bowen
A4: SALE2 | B4: 45446 | C4: CUST1056 | D4: PROD49 | E4: STORE8 | F4: 4 | G4: 914.05 | H4: 0.25 | I4: Credit Card | J4: 2742.15 | K4: =VLOOKUP(C4,'Cleaned Customer_Dim'!$A$2:$H$501,4,0) -> Female | L4: =VLOOKUP(C4, 'Cleaned Customer_Dim'!$A:$F, 6, FALSE) -> Pennsylvania | M4: =VLOOKUP(E4, 'Cleaned Stoer_ Dim'!$A$1:$E$21, 2, 0) -> Bean, Jones and Park | N4: =VLOOKUP(E4, 'Cleaned Stoer_ Dim'!$A:$E,3, 0) -> West | O4: =VLOOKUP(E4, 'Cleaned Stoer_ Dim'!$A:$E, 4, 0) -> Thompsonborough | P4: =VLOOKUP(E4, 'Cleaned Stoer_ Dim'!$A:$E, 5, 0) -> Online | Q4: =VLOOKUP(D4, 'Cleaned Product Dim Dataset'!$A:$G, 2, 0) -> Men's Roll-On Perfume | R4: =VLOOKUP(D4, 'Cleaned Product Dim Dataset'!$A:$G, 3, 0) -> Beauty | S4: =VLOOKUP(D4, 'Cleaned Product Dim Dataset'!$A:$G, 4, 0) -> Fragrance | T4: =VLOOKUP(D4, 'Cleaned Product Dim Dataset'!$A:$G, 5, 0) -> Sullivan and Sons
A5: SALE3 | B5: 45259 | C5: CUST1346 | D5: PROD76 | E5: STORE8 | F5: 1 | G5: 921.51 | H5: 0.16 | I5: COD | J5: 774.07 | K5: =VLOOKUP(C5,'Cleaned Customer_Dim'!$A$2:$H$501,4,0) -> Female | L5: =VLOOKUP(C5, 'Cleaned Customer_Dim'!$A:$F, 6, FALSE) -> Tennessee | M5: =VLOOKUP(E5, 'Cleaned Stoer_ Dim'!$A$1:$E$21, 2, 0) -> Bean, Jones and Park | N5: =VLOOKUP(E5, 'Cleaned Stoer_ Dim'!$A:$E,3, 0) -> West | O5: =VLOOKUP(E5, 'Cleaned Stoer_ Dim'!$A:$E, 4, 0) -> Thompsonborough | P5: =VLOOKUP(E5, 'Cleaned Stoer_ Dim'!$A:$E, 5, 0) -> Online | Q5: =VLOOKUP(D5, 'Cleaned Product Dim Dataset'!$A:$G, 2, 0) -> Wireless Mouse | R5: =VLOOKUP(D5, 'Cleaned Product Dim Dataset'!$A:$G, 3, 0) -> Electronics | S5: =VLOOKUP(D5, 'Cleaned Product Dim Dataset'!$A:$G, 4, 0) -> Computer | T5: =VLOOKUP(D5, 'Cleaned Product Dim Dataset'!$A:$G, 5, 0) -> Larson Ltd
A6: SALE4 | B6: 45297 | C6: CUST1493 | D6: PROD59 | E6: STORE5 | F6: 3 | G6: 745.3 | H6: 0.18 | I6: Credit Card | J6: 1833.44 | K6: =VLOOKUP(C6,'Cleaned Customer_Dim'!$A$2:$H$501,4,0) -> Male | L6: =VLOOKUP(C6, 'Cleaned Customer_Dim'!$A:$F, 6, FALSE) -> Alabama | M6: =VLOOKUP(E6, 'Cleaned Stoer_ Dim'!$A$1:$E$21, 2, 0) -> Gray Ltd | N6: =VLOOKUP(E6, 'Cleaned Stoer_ Dim'!$A:$E,3, 0) -> North | O6: =VLOOKUP(E6, 'Cleaned Stoer_ Dim'!$A:$E, 4, 0) -> New Michaelchester | P6: =VLOOKUP(E6, 'Cleaned Stoer_ Dim'!$A:$E, 5, 0) -> Outlet | Q6: =VLOOKUP(D6, 'Cleaned Product Dim Dataset'!$A:$G, 2, 0) -> Men's Hair Styling Gel | R6: =VLOOKUP(D6, 'Cleaned Product Dim Dataset'!$A:$G, 3, 0) -> Beauty | S6: =VLOOKUP(D6, 'Cleaned Product Dim Dataset'!$A:$G, 4, 0) -> Haircare | T6: =VLOOKUP(D6, 'Cleaned Product Dim Dataset'!$A:$G, 5, 0) -> Cline-Mccarthy
A7: SALE5 | B7: 45499 | C7: CUST1116 | D7: PROD15 | E7: STORE7 | F7: 3 | G7: 147.01 | H7: 0.19 | I7: COD | J7: 357.23 | K7: =VLOOKUP(C7,'Cleaned Customer_Dim'!$A$2:$H$501,4,0) -> Female | L7: =VLOOKUP(C7, 'Cleaned Customer_Dim'!$A:$F, 6, FALSE) -> Rhode Island | M7: =VLOOKUP(E7, 'Cleaned Stoer_ Dim'!$A$1:$E$21, 2, 0) -> Martinez-Mullins | N7: =VLOOKUP(E7, 'Cleaned Stoer_ Dim'!$A:$E,3, 0) -> South | O7: =VLOOKUP(E7, 'Cleaned Stoer_ Dim'!$A:$E, 4, 0) -> Williamsfurt | P7: =VLOOKUP(E7, 'Cleaned Stoer_ Dim'!$A:$E, 5, 0) -> Online | Q7: =VLOOKUP(D7, 'Cleaned Product Dim Dataset'!$A:$G, 2, 0) -> 4K Home Projector | R7: =VLOOKUP(D7, 'Cleaned Product Dim Dataset'!$A:$G, 3, 0) -> Electronics | S7: =VLOOKUP(D7, 'Cleaned Product Dim Dataset'!$A:$G, 4, 0) -> Appliances | T7: =VLOOKUP(D7, 'Cleaned Product Dim Dataset'!$A:$G, 5, 0) -> Thomas LLC
A8: SALE6 | B8: 45850 | C8: CUST1016 | D8: PROD56 | E8: STORE4 | F8: 2 | G8: 785.31 | H8: 0.15 | I8: PayPal | J8: 1335.03 | K8: =VLOOKUP(C8,'Cleaned Customer_Dim'!$A$2:$H$501,4,0) -> Female | L8: =VLOOKUP(C8, 'Cleaned Customer_Dim'!$A:$F, 6, FALSE) -> Pennsylvania | M8: =VLOOKUP(E8, 'Cleaned Stoer_ Dim'!$A$1:$E$21, 2, 0) -> Alexander Group | N8: =VLOOKUP(E8, 'Cleaned Stoer_ Dim'!$A:$E,3, 0) -> South | O8: =VLOOKUP(E8, 'Cleaned Stoer_ Dim'!$A:$E, 4, 0) -> Port Sharon | P8: =VLOOKUP(E8, 'Cleaned Stoer_ Dim'!$A:$E, 5, 0) -> Online | Q8: =VLOOKUP(D8, 'Cleaned Product Dim Dataset'!$A:$G, 2, 0) -> Premium Blanket Throw | R8: =VLOOKUP(D8, 'Cleaned Product Dim Dataset'!$A:$G, 3, 0) -> Home | S8: =VLOOKUP(D8, 'Cleaned Product Dim Dataset'!$A:$G, 4, 0) -> Decor | T8: =VLOOKUP(D8, 'Cleaned Product Dim Dataset'!$A:$G, 5, 0) -> Hernandez, Kennedy and Porter
A9: SALE7 | B9: 45248 | C9: CUST1152 | D9: PROD70 | E9: STORE8 | F9: 4 | G9: 342.39 | H9: 0.23 | I9: PayPal | J9: 1054.56 | K9: =VLOOKUP(C9,'Cleaned Customer_Dim'!$A$2:$H$501,4,0) -> Female | L9: =VLOOKUP(C9, 'Cleaned Customer_Dim'!$A:$F, 6, FALSE) -> Missouri | M9: =VLOOKUP(E9, 'Cleaned Stoer_ Dim'!$A$1:$E$21, 2, 0) -> Bean, Jones and Park | N9: =VLOOKUP(E9, 'Cleaned Stoer_ Dim'!$A:$E,3, 0) -> West | O9: =VLOOKUP(E9, 'Cleaned Stoer_ Dim'!$A:$E, 4, 0) -> Thompsonborough | P9: =VLOOKUP(E9, 'Cleaned Stoer_ Dim'!$A:$E, 5, 0) -> Online | Q9: =VLOOKUP(D9, 'Cleaned Product Dim Dataset'!$A:$G, 2, 0) -> Kitchen Storage Rack | R9: =VLOOKUP(D9, 'Cleaned Product Dim Dataset'!$A:$G, 3, 0) -> Home | S9: =VLOOKUP(D9, 'Cleaned Product Dim Dataset'!$A:$G, 4, 0) -> Storage | T9: =VLOOKUP(D9, 'Cleaned Product Dim Dataset'!$A:$G, 5, 0) -> Duran Group
A10: SALE8 | B10: 45781 | C10: CUST1187 | D10: PROD99 | E10: STORE5 | F10: 2 | G10: 448.25 | H10: 0.07 | I10: PayPal | J10: 1250.62 | K10: =VLOOKUP(C10,'Cleaned Customer_Dim'!$A$2:$H$501,4,0) -> Female | L10: =VLOOKUP(C10, 'Cleaned Customer_Dim'!$A:$F, 6, FALSE) -> Alabama | M10: =VLOOKUP(E10, 'Cleaned Stoer_ Dim'!$A$1:$E$21, 2, 0) -> Gray Ltd | N10: =VLOOKUP(E10, 'Cleaned Stoer_ Dim'!$A:$E,3, 0) -> North | O10: =VLOOKUP(E10, 'Cleaned Stoer_ Dim'!$A:$E, 4, 0) -> New Michaelchester | P10: =VLOOKUP(E10, 'Cleaned Stoer_ Dim'!$A:$E, 5, 0) -> Outlet | Q10: =VLOOKUP(D10, 'Cleaned Product Dim Dataset'!$A:$G, 2, 0) -> Stainless Steel Cookware Set | R10: =VLOOKUP(D10, 'Cleaned Product Dim Dataset'!$A:$G, 3, 0) -> Home | S10: =VLOOKUP(D10, 'Cleaned Product Dim Dataset'!$A:$G, 4, 0) -> Kitchen | T10: =VLOOKUP(D10, 'Cleaned Product Dim Dataset'!$A:$G, 5, 0) -> Campbell Ltd
A11: SALE9 | B11: 45869 | C11: CUST1464 | D11: PROD33 | E11: STORE0 | F11: 2 | G11: 873.17 | H11: 0.23 | I11: PayPal | J11: 1344.68 | K11: =VLOOKUP(C11,'Cleaned Customer_Dim'!$A$2:$H$501,4,0) -> Female | L11: =VLOOKUP(C11, 'Cleaned Customer_Dim'!$A:$F, 6, FALSE) -> Washington | M11: =VLOOKUP(E11, 'Cleaned Stoer_ Dim'!$A$1:$E$21, 2, 0) -> Rivera-Warner | N11: =VLOOKUP(E11, 'Cleaned Stoer_ Dim'!$A:$E,3, 0) -> East | O11: =VLOOKUP(E11, 'Cleaned Stoer_ Dim'!$A:$E, 4, 0) -> Washingtonfurt | P11: =VLOOKUP(E11, 'Cleaned Stoer_ Dim'!$A:$E, 5, 0) -> Flagship | Q11: =VLOOKUP(D11, 'Cleaned Product Dim Dataset'!$A:$G, 2, 0) -> Modern Wall Clock | R11: =VLOOKUP(D11, 'Cleaned Product Dim Dataset'!$A:$G, 3, 0) -> Home | S11: =VLOOKUP(D11, 'Cleaned Product Dim Dataset'!$A:$G, 4, 0) -> Decor | T11: =VLOOKUP(D11, 'Cleaned Product Dim Dataset'!$A:$G, 5, 0) -> Weiss-Watson
A12: SALE10 | B12: 45335 | C12: CUST1065 | D12: PROD24 | E12: STORE14 | F12: 1 | G12: 278.63 | H12: 0.07 | I12: Credit Card | J12: 259.13 | K12: =VLOOKUP(C12,'Cleaned Customer_Dim'!$A$2:$H$501,4,0) -> Female | L12: =VLOOKUP(C12, 'Cleaned Customer_Dim'!$A:$F, 6, FALSE) -> Nevada | M12: =VLOOKUP(E12, 'Cleaned Stoer_ Dim'!$A$1:$E$21, 2, 0) -> Mcdonald Inc | N12: =VLOOKUP(E12, 'Cleaned Stoer_ Dim'!$A:$E,3, 0) -> South | O12: =VLOOKUP(E12, 'Cleaned Stoer_ Dim'!$A:$E, 4, 0) -> Christopherland | P12: =VLOOKUP(E12, 'Cleaned Stoer_ Dim'!$A:$E, 5, 0) -> Outlet | Q12: =VLOOKUP(D12, 'Cleaned Product Dim Dataset'!$A:$G, 2, 0) -> Foldable Camping Chair | R12: =VLOOKUP(D12, 'Cleaned Product Dim Dataset'!$A:$G, 3, 0) -> Sports | S12: =VLOOKUP(D12, 'Cleaned Product Dim Dataset'!$A:$G, 4, 0) -> Outdoor | T12: =VLOOKUP(D12, 'Cleaned Product Dim Dataset'!$A:$G, 5, 0) -> Cook Ltd
A13: SALE11 | B13: 45801 | C13: CUST1320 | D13: PROD39 | E13: STORE1 | F13: 4 | G13: 286.92 | H13: 0.17 | I13: Credit Card | J13: 952.57 | K13: =VLOOKUP(C13,'Cleaned Customer_Dim'!$A$2:$H$501,4,0) -> Female | L13: =VLOOKUP(C13, 'Cleaned Customer_Dim'!$A:$F, 6, FALSE) -> Iowa | M13: =VLOOKUP(E13, 'Cleaned Stoer_ Dim'!$A$1:$E$21, 2, 0) -> Martinez, Adkins and Johnson | N13: =VLOOKUP(E13, 'Cleaned Stoer_ Dim'!$A:$E,3, 0) -> North | O13: =VLOOKUP(E13, 'Cleaned Stoer_ Dim'!$A:$E, 4, 0) -> Danielmouth | P13: =VLOOKUP(E13, 'Cleaned Stoer_ Dim'!$A:$E, 5, 0) -> Flagship | Q13: =VLOOKUP(D13, 'Cleaned Product Dim Dataset'!$A:$G, 2, 0) -> Portable Power Bank | R13: =VLOOKUP(D13, 'Cleaned Product Dim Dataset'!$A:$G, 3, 0) -> Electronics | S13: =VLOOKUP(D13, 'Cleaned Product Dim Dataset'!$A:$G, 4, 0) -> Mobile | T13: =VLOOKUP(D13, 'Cleaned Product Dim Dataset'!$A:$G, 5, 0) -> Cummings and Sons
... A27: SALE25 | B27: 45552 | C27: CUST1381 | D27: PROD5 | E27: STORE3 | F27: 4 | G27: 852.71 | H27: 0.14 | I27: PayPal | J27: 2933.32 | K27: =VLOOKUP(C27,'Cleaned Customer_Dim'!$A$2:$H$501,4,0) -> Male | L27: =VLOOKUP(C27, 'Cleaned Customer_Dim'!$A:$F, 6, FALSE) -> Alabama | M27: =VLOOKUP(E27, 'Cleaned Stoer_ Dim'!$A$1:$E$21, 2, 0) -> Johnson-Wright | N27: =VLOOKUP(E27, 'Cleaned Stoer_ Dim'!$A:$E,3, 0) -> North | O27: =VLOOKUP(E27, 'Cleaned Stoer_ Dim'!$A:$E, 4, 0) -> Hoodberg | P27: =VLOOKUP(E27, 'Cleaned Stoer_ Dim'!$A:$E, 5, 0) -> Outlet | Q27: =VLOOKUP(D27, 'Cleaned Product Dim Dataset'!$A:$G, 2, 0) -> Men's Leather Belt | R27: =VLOOKUP(D27, 'Cleaned Product Dim Dataset'!$A:$G, 3, 0) -> Clothing | S27: =VLOOKUP(D27, 'Cleaned Product Dim Dataset'!$A:$G, 4, 0) -> Accessories | T27: =VLOOKUP(D27, 'Cleaned Product Dim Dataset'!$A:$G, 5, 0) -> Baldwin, Garza and Gonzalez
A28: SALE26 | B28: 45294 | C28: CUST1213 | D28: PROD98 | E28: STORE8 | F28: 4 | G28: 156.16 | H28: =1-(J28/(F28*G28)) -> 0.040007044 | I28: Credit Card | J28: 599.65 | K28: =VLOOKUP(C28,'Cleaned Customer_Dim'!$A$2:$H$501,4,0) -> Female | L28: =VLOOKUP(C28, 'Cleaned Customer_Dim'!$A:$F, 6, FALSE) -> North Dakota | M28: =VLOOKUP(E28, 'Cleaned Stoer_ Dim'!$A$1:$E$21, 2, 0) -> Bean, Jones and Park | N28: =VLOOKUP(E28, 'Cleaned Stoer_ Dim'!$A:$E,3, 0) -> West | O28: =VLOOKUP(E28, 'Cleaned Stoer_ Dim'!$A:$E, 4, 0) -> Thompsonborough | P28: =VLOOKUP(E28, 'Cleaned Stoer_ Dim'!$A:$E, 5, 0) -> Online | Q28: =VLOOKUP(D28, 'Cleaned Product Dim Dataset'!$A:$G, 2, 0) -> Portable Bluetooth Speaker | R28: =VLOOKUP(D28, 'Cleaned Product Dim Dataset'!$A:$G, 3, 0) -> Electronics | S28: =VLOOKUP(D28, 'Cleaned Product Dim Dataset'!$A:$G, 4, 0) -> Audio | T28: =VLOOKUP(D28, 'Cleaned Product Dim Dataset'!$A:$G, 5, 0) -> Flores-King
A29: SALE27 | B29: 45710 | C29: CUST1200 | D29: PROD77 | E29: STORE8 | F29: 3 | G29: 815.49 | H29: 0.17 | I29: Credit Card | J29: 2030.57 | K29: =VLOOKUP(C29,'Cleaned Customer_Dim'!$A$2:$H$501,4,0) -> Male | L29: =VLOOKUP(C29, 'Cleaned Customer_Dim'!$A:$F, 6, FALSE) -> Maine | M29: =VLOOKUP(E29, 'Cleaned Stoer_ Dim'!$A$1:$E$21, 2, 0) -> Bean, Jones and Park | N29: =VLOOKUP(E29, 'Cleaned Stoer_ Dim'!$A:$E,3, 0) -> West | O29: =VLOOKUP(E29, 'Cleaned Stoer_ Dim'!$A:$E, 4, 0) -> Thompsonborough | P29: =VLOOKUP(E29, 'Cleaned Stoer_ Dim'!$A:$E, 5, 0) -> Online | Q29: =VLOOKUP(D29, 'Cleaned Product Dim Dataset'!$A:$G, 2, 0) -> WiFi Mesh Router | R29: =VLOOKUP(D29, 'Cleaned Product Dim Dataset'!$A:$G, 3, 0) -> Electronics | S29: =VLOOKUP(D29, 'Cleaned Product Dim Dataset'!$A:$G, 4, 0) -> Appliances | T29: =VLOOKUP(D29, 'Cleaned Product Dim Dataset'!$A:$G, 5, 0) -> White, Reeves and Woods
A30: SALE28 | B30: 45923 | C30: CUST1148 | D30: PROD13 | E30: STORE2 | F30: 2 | G30: 74.21 | H30: 0.11 | I30: PayPal | J30: 132.09 | K30: =VLOOKUP(C30,'Cleaned Customer_Dim'!$A$2:$H$501,4,0) -> Female | L30: =VLOOKUP(C30, 'Cleaned Customer_Dim'!$A:$F, 6, FALSE) -> Wisconsin | M30: =VLOOKUP(E30, 'Cleaned Stoer_ Dim'!$A$1:$E$21, 2, 0) -> Black-Horn | N30: =VLOOKUP(E30, 'Cleaned Stoer_ Dim'!$A:$E,3, 0) -> South | O30: =VLOOKUP(E30, 'Cleaned Stoer_ Dim'!$A:$E, 4, 0) -> North Nancyview | P30: =VLOOKUP(E30, 'Cleaned Stoer_ Dim'!$A:$E, 5, 0) -> Outlet | Q30: =VLOOKUP(D30, 'Cleaned Product Dim Dataset'!$A:$G, 2, 0) -> USB-C Fast Charger | R30: =VLOOKUP(D30, 'Cleaned Product Dim Dataset'!$A:$G, 3, 0) -> Electronics | S30: =VLOOKUP(D30, 'Cleaned Product Dim Dataset'!$A:$G, 4, 0) -> Accessories | T30: =VLOOKUP(D30, 'Cleaned Product Dim Dataset'!$A:$G, 5, 0) -> Dawson-Perkins
A31: SALE29 | B31: 45302 | C31: CUST1348 | D31: PROD99 | E31: STORE3 | F31: 2 | G31: 451.67 | H31: 0.15 | I31: Credit Card | J31: 1535.68 | K31: =VLOOKUP(C31,'Cleaned Customer_Dim'!$A$2:$H$501,4,0) -> Male | L31: =VLOOKUP(C31, 'Cleaned Customer_Dim'!$A:$F, 6, FALSE) -> Pennsylvania | M31: =VLOOKUP(E31, 'Cleaned Stoer_ Dim'!$A$1:$E$21, 2, 0) -> Johnson-Wright | N31: =VLOOKUP(E31, 'Cleaned Stoer_ Dim'!$A:$E,3, 0) -> North | O31: =VLOOKUP(E31, 'Cleaned Stoer_ Dim'!$A:$E, 4, 0) -> Hoodberg | P31: =VLOOKUP(E31, 'Cleaned Stoer_ Dim'!$A:$E, 5, 0) -> Outlet | Q31: =VLOOKUP(D31, 'Cleaned Product Dim Dataset'!$A:$G, 2, 0) -> Stainless Steel Cookware Set | R31: =VLOOKUP(D31, 'Cleaned Product Dim Dataset'!$A:$G, 3, 0) -> Home | S31: =VLOOKUP(D31, 'Cleaned Product Dim Dataset'!$A:$G, 4, 0) -> Kitchen | T31: =VLOOKUP(D31, 'Cleaned Product Dim Dataset'!$A:$G, 5, 0) -> Campbell Ltd
A32: SALE30 | B32: 45217 | C32: CUST1028 | D32: PROD5 | E32: STORE19 | F32: 1 | G32: 429.38 | H32: 0.13 | I32: PayPal | J32: 373.56 | K32: =VLOOKUP(C32,'Cleaned Customer_Dim'!$A$2:$H$501,4,0) -> Female | L32: =VLOOKUP(C32, 'Cleaned Customer_Dim'!$A:$F, 6, FALSE) -> New Jersey | M32: =VLOOKUP(E32, 'Cleaned Stoer_ Dim'!$A$1:$E$21, 2, 0) -> Mann-Austin | N32: =VLOOKUP(E32, 'Cleaned Stoer_ Dim'!$A:$E,3, 0) -> East | O32: =VLOOKUP(E32, 'Cleaned Stoer_ Dim'!$A:$E, 4, 0) -> Vasquezborough | P32: =VLOOKUP(E32, 'Cleaned Stoer_ Dim'!$A:$E, 5, 0) -> Online | Q32: =VLOOKUP(D32, 'Cleaned Product Dim Dataset'!$A:$G, 2, 0) -> Men's Leather Belt | R32: =VLOOKUP(D32, 'Cleaned Product Dim Dataset'!$A:$G, 3, 0) -> Clothing | S32: =VLOOKUP(D32, 'Cleaned Product Dim Dataset'!$A:$G, 4, 0) -> Accessories | T32: =VLOOKUP(D32, 'Cleaned Product Dim Dataset'!$A:$G, 5, 0) -> Baldwin, Garza and Gonzalez
A33: SALE31 | B33: 45593 | C33: CUST1412 | D33: PROD53 | E33: STORE12 | F33: 2 | G33: 148.96 | H33: 0.03 | I33: COD | J33: 288.98 | K33: =VLOOKUP(C33,'Cleaned Customer_Dim'!$A$2:$H$501,4,0) -> Female | L33: =VLOOKUP(C33, 'Cleaned Customer_Dim'!$A:$F, 6, FALSE) -> Michigan | M33: =VLOOKUP(E33, 'Cleaned Stoer_ Dim'!$A$1:$E$21, 2, 0) -> Thomas, Bridges and Harris | N33: =VLOOKUP(E33, 'Cleaned Stoer_ Dim'!$A:$E,3, 0) -> North | O33: =VLOOKUP(E33, 'Cleaned Stoer_ Dim'!$A:$E, 4, 0) -> Sabrinatown | P33: =VLOOKUP(E33, 'Cleaned Stoer_ Dim'!$A:$E, 5, 0) -> Online | Q33: =VLOOKUP(D33, 'Cleaned Product Dim Dataset'!$A:$G, 2, 0) -> Men's Track Pants | R33: =VLOOKUP(D33, 'Cleaned Product Dim Dataset'!$A:$G, 3, 0) -> Clothing | S33: =VLOOKUP(D33, 'Cleaned Product Dim Dataset'!$A:$G, 4, 0) -> Bottoms | T33: =VLOOKUP(D33, 'Cleaned Product Dim Dataset'!$A:$G, 5, 0) -> Hamilton, Woods and Walker
A34: SALE32 | B34: 45597 | C34: CUST1398 | D34: PROD75 | E34: STORE8 | F34: 4 | G34: 313.83 | H34: 0.08 | I34: Credit Card | J34: 1154.89 | K34: =VLOOKUP(C34,'Cleaned Customer_Dim'!$A$2:$H$501,4,0) -> Male | L34: =VLOOKUP(C34, 'Cleaned Customer_Dim'!$A:$F, 6, FALSE) -> New Hampshire | M34: =VLOOKUP(E34, 'Cleaned Stoer_ Dim'!$A$1:$E$21, 2, 0) -> Bean, Jones and Park | N34: =VLOOKUP(E34, 'Cleaned Stoer_ Dim'!$A:$E,3, 0) -> West | O34: =VLOOKUP(E34, 'Cleaned Stoer_ Dim'!$A:$E, 4, 0) -> Thompsonborough | P34: =VLOOKUP(E34, 'Cleaned Stoer_ Dim'!$A:$E, 5, 0) -> Online | Q34: =VLOOKUP(D34, 'Cleaned Product Dim Dataset'!$A:$G, 2, 0) -> Women's Ankle Boots | R34: =VLOOKUP(D34, 'Cleaned Product Dim Dataset'!$A:$G, 3, 0) -> Clothing | S34: =VLOOKUP(D34, 'Cleaned Product Dim Dataset'!$A:$G, 4, 0) -> Footwear | T34: =VLOOKUP(D34, 'Cleaned Product Dim Dataset'!$A:$G, 5, 0) -> Poole PLC
A35: SALE33 | B35: 45620 | C35: CUST1453 | D35: PROD12 | E35: STORE6 | F35: 2 | G35: 717.31 | H35: 0.15 | I35: Credit Card | J35: 1219.43 | K35: =VLOOKUP(C35,'Cleaned Customer_Dim'!$A$2:$H$501,4,0) -> Female | L35: =VLOOKUP(C35, 'Cleaned Customer_Dim'!$A:$F, 6, FALSE) -> Hawaii | M35: =VLOOKUP(E35, 'Cleaned Stoer_ Dim'!$A$1:$E$21, 2, 0) -> Benson-Elliott | N35: =VLOOKUP(E35, 'Cleaned Stoer_ Dim'!$A:$E,3, 0) -> East | O35: =VLOOKUP(E35, 'Cleaned Stoer_ Dim'!$A:$E, 4, 0) -> Port Josephberg | P35: =VLOOKUP(E35, 'Cleaned Stoer_ Dim'!$A:$E, 5, 0) -> Online | Q35: =VLOOKUP(D35, 'Cleaned Product Dim Dataset'!$A:$G, 2, 0) -> Hair Strengthening Shampoo | R35: =VLOOKUP(D35, 'Cleaned Product Dim Dataset'!$A:$G, 3, 0) -> Beauty | S35: =VLOOKUP(D35, 'Cleaned Product Dim Dataset'!$A:$G, 4, 0) -> Haircare | T35: =VLOOKUP(D35, 'Cleaned Product Dim Dataset'!$A:$G, 5, 0) -> Rice LLC
A36: SALE34 | B36: 45215 | C36: CUST1344 | D36: PROD79 | E36: STORE1 | F36: 2 | G36: 873.22 | H36: 0.18 | I36: Credit Card | J36: 2148.12 | K36: =VLOOKUP(C36,'Cleaned Customer_Dim'!$A$2:$H$501,4,0) -> Male | L36: =VLOOKUP(C36, 'Cleaned Customer_Dim'!$A:$F, 6, FALSE) -> New Mexico | M36: =VLOOKUP(E36, 'Cleaned Stoer_ Dim'!$A$1:$E$21, 2, 0) -> Martinez, Adkins and Johnson | N36: =VLOOKUP(E36, 'Cleaned Stoer_ Dim'!$A:$E,3, 0) -> North | O36: =VLOOKUP(E36, 'Cleaned Stoer_ Dim'!$A:$E, 4, 0) -> Danielmouth | P36: =VLOOKUP(E36, 'Cleaned Stoer_ Dim'!$A:$E, 5, 0) -> Flagship | Q36: =VLOOKUP(D36, 'Cleaned Product Dim Dataset'!$A:$G, 2, 0) -> Decorative Lamp Shade | R36: =VLOOKUP(D36, 'Cleaned Product Dim Dataset'!$A:$G, 3, 0) -> Home | S36: =VLOOKUP(D36, 'Cleaned Product Dim Dataset'!$A:$G, 4, 0) -> Lighting | T36: =VLOOKUP(D36, 'Cleaned Product Dim Dataset'!$A:$G, 5, 0) -> Ramirez-Hanson
A37: SALE35 | B37: 45878 | C37: CUST1218 | D37: PROD16 | E37: STORE3 | F37: 4 | G37: 109.36 | H37: 0.19 | I37: COD | J37: 354.33 | K37: =VLOOKUP(C37,'Cleaned Customer_Dim'!$A$2:$H$501,4,0) -> Male | L37: =VLOOKUP(C37, 'Cleaned Customer_Dim'!$A:$F, 6, FALSE) -> California | M37: =VLOOKUP(E37, 'Cleaned Stoer_ Dim'!$A$1:$E$21, 2, 0) -> Johnson-Wright | N37: =VLOOKUP(E37, 'Cleaned Stoer_ Dim'!$A:$E,3, 0) -> North | O37: =VLOOKUP(E37, 'Cleaned Stoer_ Dim'!$A:$E, 4, 0) -> Hoodberg | P37: =VLOOKUP(E37, 'Cleaned Stoer_ Dim'!$A:$E, 5, 0) -> Outlet | Q37: =VLOOKUP(D37, 'Cleaned Product Dim Dataset'!$A:$G, 2, 0) -> Beard Grooming Kit | R37: =VLOOKUP(D37, 'Cleaned Product Dim Dataset'!$A:$G, 3, 0) -> Beauty | S37: =VLOOKUP(D37, 'Cleaned Product Dim Dataset'!$A:$G, 4, 0) -> Grooming | T37: =VLOOKUP(D37, 'Cleaned Product Dim Dataset'!$A:$G, 5, 0) -> Erickson-Green
A38: SALE36 | B38: 45635 | C38: CUST1086 | D38: PROD5 | E38: STORE7 | F38: 3 | G38: 559.52 | H38: 0.16 | I38: PayPal | J38: 1409.99 | K38: =VLOOKUP(C38,'Cleaned Customer_Dim'!$A$2:$H$501,4,0) -> Female | L38: =VLOOKUP(C38, 'Cleaned Customer_Dim'!$A:$F, 6, FALSE) -> Mississippi | M38: =VLOOKUP(E38, 'Cleaned Stoer_ Dim'!$A$1:$E$21, 2, 0) -> Martinez-Mullins | N38: =VLOOKUP(E38, 'Cleaned Stoer_ Dim'!$A:$E,3, 0) -> South | O38: =VLOOKUP(E38, 'Cleaned Stoer_ Dim'!$A:$E, 4, 0) -> Williamsfurt | P38: =VLOOKUP(E38, 'Cleaned Stoer_ Dim'!$A:$E, 5, 0) -> Online | Q38: =VLOOKUP(D38, 'Cleaned Product Dim Dataset'!$A:$G, 2, 0) -> Men's Leather Belt | R38: =VLOOKUP(D38, 'Cleaned Product Dim Dataset'!$A:$G, 3, 0) -> Clothing | S38: =VLOOKUP(D38, 'Cleaned Product Dim Dataset'!$A:$G, 4, 0) -> Accessories | T38: =VLOOKUP(D38, 'Cleaned Product Dim Dataset'!$A:$G, 5, 0) -> Baldwin, Garza and Gonzalez
A39: SALE37 | B39: 45329 | C39: CUST1492 | D39: PROD10 | E39: STORE17 | F39: 3 | G39: 121.76 | H39: 0.27 | I39: PayPal | J39: 266.65 | K39: =VLOOKUP(C39,'Cleaned Customer_Dim'!$A$2:$H$501,4,0) -> Female | L39: =VLOOKUP(C39, 'Cleaned Customer_Dim'!$A:$F, 6, FALSE) -> Florida | M39: =VLOOKUP(E39, 'Cleaned Stoer_ Dim'!$A$1:$E$21, 2, 0) -> Holloway Ltd | N39: =VLOOKUP(E39, 'Cleaned Stoer_ Dim'!$A:$E,3, 0) -> North | O39: =VLOOKUP(E39, 'Cleaned Stoer_ Dim'!$A:$E, 4, 0) -> Bensonhaven | P39: =VLOOKUP(E39, 'Cleaned Stoer_ Dim'!$A:$E, 5, 0) -> Flagship | Q39: =VLOOKUP(D39, 'Cleaned Product Dim Dataset'!$A:$G, 2, 0) -> Ceramic Kitchen Bowl Set | R39: =VLOOKUP(D39, 'Cleaned Product Dim Dataset'!$A:$G, 3, 0) -> Home | S39: =VLOOKUP(D39, 'Cleaned Product Dim Dataset'!$A:$G, 4, 0) -> Kitchen | T39: =VLOOKUP(D39, 'Cleaned Product Dim Dataset'!$A:$G, 5, 0) -> Hamilton Group
A40: SALE38 | B40: 45378 | C40: CUST1189 | D40: PROD33 | E40: STORE13 | F40: 4 | G40: 735.32 | H40: 0.06 | I40: COD | J40: 2764.8 | K40: =VLOOKUP(C40,'Cleaned Customer_Dim'!$A$2:$H$501,4,0) -> Male | L40: =VLOOKUP(C40, 'Cleaned Customer_Dim'!$A:$F, 6, FALSE) -> Kentucky | M40: =VLOOKUP(E40, 'Cleaned Stoer_ Dim'!$A$1:$E$21, 2, 0) -> Gardner, Humphrey and Contreras | N40: =VLOOKUP(E40, 'Cleaned Stoer_ Dim'!$A:$E,3, 0) -> East | O40: =VLOOKUP(E40, 'Cleaned Stoer_ Dim'!$A:$E, 4, 0) -> Johnsonville | P40: =VLOOKUP(E40, 'Cleaned Stoer_ Dim'!$A:$E, 5, 0) -> Flagship | Q40: =VLOOKUP(D40, 'Cleaned Product Dim Dataset'!$A:$G, 2, 0) -> Modern Wall Clock | R40: =VLOOKUP(D40, 'Cleaned Product Dim Dataset'!$A:$G, 3, 0) -> Home | S40: =VLOOKUP(D40, 'Cleaned Product Dim Dataset'!$A:$G, 4, 0) -> Decor | T40: =VLOOKUP(D40, 'Cleaned Product Dim Dataset'!$A:$G, 5, 0) -> Weiss-Watson
... A53: SALE51 | B53: 45689 | C53: CUST1142 | D53: PROD69 | E53: STORE7 | F53: 3 | G53: 76.57 | H53: 0.26 | I53: Credit Card | J53: 169.99 | K53: =VLOOKUP(C53,'Cleaned Customer_Dim'!$A$2:$H$501,4,0) -> Male | L53: =VLOOKUP(C53, 'Cleaned Customer_Dim'!$A:$F, 6, FALSE) -> Montana | M53: =VLOOKUP(E53, 'Cleaned Stoer_ Dim'!$A$1:$E$21, 2, 0) -> Martinez-Mullins | N53: =VLOOKUP(E53, 'Cleaned Stoer_ Dim'!$A:$E,3, 0) -> South | O53: =VLOOKUP(E53, 'Cleaned Stoer_ Dim'!$A:$E, 4, 0) -> Williamsfurt | P53: =VLOOKUP(E53, 'Cleaned Stoer_ Dim'!$A:$E, 5, 0) -> Online | Q53: =VLOOKUP(D53, 'Cleaned Product Dim Dataset'!$A:$G, 2, 0) -> Men's Sports Shorts | R53: =VLOOKUP(D53, 'Cleaned Product Dim Dataset'!$A:$G, 3, 0) -> Clothing | S53: =VLOOKUP(D53, 'Cleaned Product Dim Dataset'!$A:$G, 4, 0) -> Bottoms | T53: =VLOOKUP(D53, 'Cleaned Product Dim Dataset'!$A:$G, 5, 0) -> Fitzpatrick Ltd
A54: SALE52 | B54: 45894 | C54: CUST1148 | D54: PROD89 | E54: STORE6 | F54: 3 | G54: 513.98 | H54: =1-(J54/(F54*G54)) -> 0.68477373 | I54: Credit Card | J54: 486.06 | K54: =VLOOKUP(C54,'Cleaned Customer_Dim'!$A$2:$H$501,4,0) -> Female | L54: =VLOOKUP(C54, 'Cleaned Customer_Dim'!$A:$F, 6, FALSE) -> Wisconsin | M54: =VLOOKUP(E54, 'Cleaned Stoer_ Dim'!$A$1:$E$21, 2, 0) -> Benson-Elliott | N54: =VLOOKUP(E54, 'Cleaned Stoer_ Dim'!$A:$E,3, 0) -> East | O54: =VLOOKUP(E54, 'Cleaned Stoer_ Dim'!$A:$E, 4, 0) -> Port Josephberg | P54: =VLOOKUP(E54, 'Cleaned Stoer_ Dim'!$A:$E, 5, 0) -> Online | Q54: =VLOOKUP(D54, 'Cleaned Product Dim Dataset'!$A:$G, 2, 0) -> Face Foundation Kit | R54: =VLOOKUP(D54, 'Cleaned Product Dim Dataset'!$A:$G, 3, 0) -> Beauty | S54: =VLOOKUP(D54, 'Cleaned Product Dim Dataset'!$A:$G, 4, 0) -> Makeup | T54: =VLOOKUP(D54, 'Cleaned Product Dim Dataset'!$A:$G, 5, 0) -> Taylor-Elliott
A55: SALE53 | B55: 45677 | C55: CUST1324 | D55: PROD20 | E55: STORE8 | F55: 1 | G55: 900.35 | H55: 0.13 | I55: COD | J55: 783.3 | K55: =VLOOKUP(C55,'Cleaned Customer_Dim'!$A$2:$H$501,4,0) -> Male | L55: =VLOOKUP(C55, 'Cleaned Customer_Dim'!$A:$F, 6, FALSE) -> Oklahoma | M55: =VLOOKUP(E55, 'Cleaned Stoer_ Dim'!$A$1:$E$21, 2, 0) -> Bean, Jones and Park | N55: =VLOOKUP(E55, 'Cleaned Stoer_ Dim'!$A:$E,3, 0) -> West | O55: =VLOOKUP(E55, 'Cleaned Stoer_ Dim'!$A:$E, 4, 0) -> Thompsonborough | P55: =VLOOKUP(E55, 'Cleaned Stoer_ Dim'!$A:$E, 5, 0) -> Online | Q55: =VLOOKUP(D55, 'Cleaned Product Dim Dataset'!$A:$G, 2, 0) -> Outdoor Sports Water Bottle | R55: =VLOOKUP(D55, 'Cleaned Product Dim Dataset'!$A:$G, 3, 0) -> Sports | S55: =VLOOKUP(D55, 'Cleaned Product Dim Dataset'!$A:$G, 4, 0) -> Accessories | T55: =VLOOKUP(D55, 'Cleaned Product Dim Dataset'!$A:$G, 5, 0) -> Soto-Ellis
A56: SALE54 | B56: 45706 | C56: CUST1095 | D56: PROD40 | E56: STORE10 | F56: 4 | G56: 428.09 | H56: 0.07 | I56: Credit Card | J56: 1592.49 | K56: =VLOOKUP(C56,'Cleaned Customer_Dim'!$A$2:$H$501,4,0) -> Female | L56: =VLOOKUP(C56, 'Cleaned Customer_Dim'!$A:$F, 6, FALSE) -> New York | M56: =VLOOKUP(E56, 'Cleaned Stoer_ Dim'!$A$1:$E$21, 2, 0) -> Hill, Wagner and Ballard | N56: =VLOOKUP(E56, 'Cleaned Stoer_ Dim'!$A:$E,3, 0) -> East | O56: =VLOOKUP(E56, 'Cleaned Stoer_ Dim'!$A:$E, 4, 0) -> East Davidville | P56: =VLOOKUP(E56, 'Cleaned Stoer_ Dim'!$A:$E, 5, 0) -> Online | Q56: =VLOOKUP(D56, 'Cleaned Product Dim Dataset'!$A:$G, 2, 0) -> Noise-Canceling Headphones | R56: =VLOOKUP(D56, 'Cleaned Product Dim Dataset'!$A:$G, 3, 0) -> Electronics | S56: =VLOOKUP(D56, 'Cleaned Product Dim Dataset'!$A:$G, 4, 0) -> Audio | T56: =VLOOKUP(D56, 'Cleaned Product Dim Dataset'!$A:$G, 5, 0) -> Taylor-Hart
A57: SALE55 | B57: 45589 | C57: CUST1416 | D57: PROD49 | E57: STORE11 | F57: 2 | G57: 559.71 | H57: 0.3 | I57: COD | J57: 783.59 | K57: =VLOOKUP(C57,'Cleaned Customer_Dim'!$A$2:$H$501,4,0) -> Male | L57: =VLOOKUP(C57, 'Cleaned Customer_Dim'!$A:$F, 6, FALSE) -> Wisconsin | M57: =VLOOKUP(E57, 'Cleaned Stoer_ Dim'!$A$1:$E$21, 2, 0) -> Aguirre-Keller | N57: =VLOOKUP(E57, 'Cleaned Stoer_ Dim'!$A:$E,3, 0) -> South | O57: =VLOOKUP(E57, 'Cleaned Stoer_ Dim'!$A:$E, 4, 0) -> Lake Michael | P57: =VLOOKUP(E57, 'Cleaned Stoer_ Dim'!$A:$E, 5, 0) -> Online | Q57: =VLOOKUP(D57, 'Cleaned Product Dim Dataset'!$A:$G, 2, 0) -> Men's Roll-On Perfume | R57: =VLOOKUP(D57, 'Cleaned Product Dim Dataset'!$A:$G, 3, 0) -> Beauty | S57: =VLOOKUP(D57, 'Cleaned Product Dim Dataset'!$A:$G, 4, 0) -> Fragrance | T57: =VLOOKUP(D57, 'Cleaned Product Dim Dataset'!$A:$G, 5, 0) -> Sullivan and Sons
A58: SALE56 | B58: 45282 | C58: CUST1080 | D58: PROD34 | E58: STORE6 | F58: 2 | G58: 833.7 | H58: 0.06 | I58: PayPal | J58: 1567.36 | K58: =VLOOKUP(C58,'Cleaned Customer_Dim'!$A$2:$H$501,4,0) -> Female | L58: =VLOOKUP(C58, 'Cleaned Customer_Dim'!$A:$F, 6, FALSE) -> New Mexico | M58: =VLOOKUP(E58, 'Cleaned Stoer_ Dim'!$A$1:$E$21, 2, 0) -> Benson-Elliott | N58: =VLOOKUP(E58, 'Cleaned Stoer_ Dim'!$A:$E,3, 0) -> East | O58: =VLOOKUP(E58, 'Cleaned Stoer_ Dim'!$A:$E, 4, 0) -> Port Josephberg | P58: =VLOOKUP(E58, 'Cleaned Stoer_ Dim'!$A:$E, 5, 0) -> Online | Q58: =VLOOKUP(D58, 'Cleaned Product Dim Dataset'!$A:$G, 2, 0) -> Gaming Mechanical Keyboard | R58: =VLOOKUP(D58, 'Cleaned Product Dim Dataset'!$A:$G, 3, 0) -> Electronics | S58: =VLOOKUP(D58, 'Cleaned Product Dim Dataset'!$A:$G, 4, 0) -> Computer | T58: =VLOOKUP(D58, 'Cleaned Product Dim Dataset'!$A:$G, 5, 0) -> Lucero LLC
A59: SALE57 | B59: 45462 | C59: CUST1467 | D59: PROD47 | E59: STORE14 | F59: 2 | G59: 680.16 | H59: 0.28 | I59: Credit Card | J59: 979.43 | K59: =VLOOKUP(C59,'Cleaned Customer_Dim'!$A$2:$H$501,4,0) -> Female | L59: =VLOOKUP(C59, 'Cleaned Customer_Dim'!$A:$F, 6, FALSE) -> Vermont | M59: =VLOOKUP(E59, 'Cleaned Stoer_ Dim'!$A$1:$E$21, 2, 0) -> Mcdonald Inc | N59: =VLOOKUP(E59, 'Cleaned Stoer_ Dim'!$A:$E,3, 0) -> South | O59: =VLOOKUP(E59, 'Cleaned Stoer_ Dim'!$A:$E, 4, 0) -> Christopherland | P59: =VLOOKUP(E59, 'Cleaned Stoer_ Dim'!$A:$E, 5, 0) -> Outlet | Q59: =VLOOKUP(D59, 'Cleaned Product Dim Dataset'!$A:$G, 2, 0) -> Makeup Brush Set | R59: =VLOOKUP(D59, 'Cleaned Product Dim Dataset'!$A:$G, 3, 0) -> Beauty | S59: =VLOOKUP(D59, 'Cleaned Product Dim Dataset'!$A:$G, 4, 0) -> Makeup | T59: =VLOOKUP(D59, 'Cleaned Product Dim Dataset'!$A:$G, 5, 0) -> Cook Inc
A60: SALE58 | B60: 45633 | C60: CUST1404 | D60: PROD15 | E60: STORE7 | F60: 4 | G60: 733.42 | H60: =1-(J60/(F60*G60)) -> 0.13000055 | I60: PayPal | J60: 2552.3 | K60: =VLOOKUP(C60,'Cleaned Customer_Dim'!$A$2:$H$501,4,0) -> Female | L60: =VLOOKUP(C60, 'Cleaned Customer_Dim'!$A:$F, 6, FALSE) -> Arkansas | M60: =VLOOKUP(E60, 'Cleaned Stoer_ Dim'!$A$1:$E$21, 2, 0) -> Martinez-Mullins | N60: =VLOOKUP(E60, 'Cleaned Stoer_ Dim'!$A:$E,3, 0) -> South | O60: =VLOOKUP(E60, 'Cleaned Stoer_ Dim'!$A:$E, 4, 0) -> Williamsfurt | P60: =VLOOKUP(E60, 'Cleaned Stoer_ Dim'!$A:$E, 5, 0) -> Online | Q60: =VLOOKUP(D60, 'Cleaned Product Dim Dataset'!$A:$G, 2, 0) -> 4K Home Projector | R60: =VLOOKUP(D60, 'Cleaned Product Dim Dataset'!$A:$G, 3, 0) -> Electronics | S60: =VLOOKUP(D60, 'Cleaned Product Dim Dataset'!$A:$G, 4, 0) -> Appliances | T60: =VLOOKUP(D60, 'Cleaned Product Dim Dataset'!$A:$G, 5, 0) -> Thomas LLC
A61: SALE59 | B61: 45257 | C61: CUST1367 | D61: PROD89 | E61: STORE11 | F61: 1 | G61: 996.33 | H61: 0.23 | I61: PayPal | J61: 767.17 | K61: =VLOOKUP(C61,'Cleaned Customer_Dim'!$A$2:$H$501,4,0) -> Male | L61: =VLOOKUP(C61, 'Cleaned Customer_Dim'!$A:$F, 6, FALSE) -> Ohio | M61: =VLOOKUP(E61, 'Cleaned Stoer_ Dim'!$A$1:$E$21, 2, 0) -> Aguirre-Keller | N61: =VLOOKUP(E61, 'Cleaned Stoer_ Dim'!$A:$E,3, 0) -> South | O61: =VLOOKUP(E61, 'Cleaned Stoer_ Dim'!$A:$E, 4, 0) -> Lake Michael | P61: =VLOOKUP(E61, 'Cleaned Stoer_ Dim'!$A:$E, 5, 0) -> Online | Q61: =VLOOKUP(D61, 'Cleaned Product Dim Dataset'!$A:$G, 2, 0) -> Face Foundation Kit | R61: =VLOOKUP(D61, 'Cleaned Product Dim Dataset'!$A:$G, 3, 0) -> Beauty | S61: =VLOOKUP(D61, 'Cleaned Product Dim Dataset'!$A:$G, 4, 0) -> Makeup | T61: =VLOOKUP(D61, 'Cleaned Product Dim Dataset'!$A:$G, 5, 0) -> Taylor-Elliott
A62: SALE60 | B62: 45854 | C62: CUST1408 | D62: PROD31 | E62: STORE10 | F62: 1 | G62: 198.83 | H62: 0.09 | I62: COD | J62: 180.94 | K62: =VLOOKUP(C62,'Cleaned Customer_Dim'!$A$2:$H$501,4,0) -> Male | L62: =VLOOKUP(C62, 'Cleaned Customer_Dim'!$A:$F, 6, FALSE) -> New Jersey | M62: =VLOOKUP(E62, 'Cleaned Stoer_ Dim'!$A$1:$E$21, 2, 0) -> Hill, Wagner and Ballard | N62: =VLOOKUP(E62, 'Cleaned Stoer_ Dim'!$A:$E,3, 0) -> East | O62: =VLOOKUP(E62, 'Cleaned Stoer_ Dim'!$A:$E, 4, 0) -> East Davidville | P62: =VLOOKUP(E62, 'Cleaned Stoer_ Dim'!$A:$E, 5, 0) -> Online | Q62: =VLOOKUP(D62, 'Cleaned Product Dim Dataset'!$A:$G, 2, 0) -> Basketball | R62: =VLOOKUP(D62, 'Cleaned Product Dim Dataset'!$A:$G, 3, 0) -> Sports | S62: =VLOOKUP(D62, 'Cleaned Product Dim Dataset'!$A:$G, 4, 0) -> Team Sports | T62: =VLOOKUP(D62, 'Cleaned Product Dim Dataset'!$A:$G, 5, 0) -> Nolan-Snow
A63: SALE61 | B63: 45716 | C63: CUST1239 | D63: PROD19 | E63: STORE7 | F63: 1 | G63: 374.92 | H63: 0.18 | I63: PayPal | J63: 307.43 | K63: =VLOOKUP(C63,'Cleaned Customer_Dim'!$A$2:$H$501,4,0) -> Female | L63: =VLOOKUP(C63, 'Cleaned Customer_Dim'!$A:$F, 6, FALSE) -> Nevada | M63: =VLOOKUP(E63, 'Cleaned Stoer_ Dim'!$A$1:$E$21, 2, 0) -> Martinez-Mullins | N63: =VLOOKUP(E63, 'Cleaned Stoer_ Dim'!$A:$E,3, 0) -> South | O63: =VLOOKUP(E63, 'Cleaned Stoer_ Dim'!$A:$E, 4, 0) -> Williamsfurt | P63: =VLOOKUP(E63, 'Cleaned Stoer_ Dim'!$A:$E, 5, 0) -> Online | Q63: =VLOOKUP(D63, 'Cleaned Product Dim Dataset'!$A:$G, 2, 0) -> Knee Support Brace | R63: =VLOOKUP(D63, 'Cleaned Product Dim Dataset'!$A:$G, 3, 0) -> Sports | S63: =VLOOKUP(D63, 'Cleaned Product Dim Dataset'!$A:$G, 4, 0) -> Equipment | T63: =VLOOKUP(D63, 'Cleaned Product Dim Dataset'!$A:$G, 5, 0) -> May-Reese
A64: SALE62 | B64: 45515 | C64: CUST1464 | D64: PROD93 | E64: STORE16 | F64: 1 | G64: 468.94 | H64: 0.12 | I64: Credit Card | J64: 412.67 | K64: =VLOOKUP(C64,'Cleaned Customer_Dim'!$A$2:$H$501,4,0) -> Female | L64: =VLOOKUP(C64, 'Cleaned Customer_Dim'!$A:$F, 6, FALSE) -> Washington | M64: =VLOOKUP(E64, 'Cleaned Stoer_ Dim'!$A$1:$E$21, 2, 0) -> Frederick-Wright | N64: =VLOOKUP(E64, 'Cleaned Stoer_ Dim'!$A:$E,3, 0) -> West | O64: =VLOOKUP(E64, 'Cleaned Stoer_ Dim'!$A:$E, 4, 0) -> New Jimmymouth | P64: =VLOOKUP(E64, 'Cleaned Stoer_ Dim'!$A:$E, 5, 0) -> Flagship | Q64: =VLOOKUP(D64, 'Cleaned Product Dim Dataset'!$A:$G, 2, 0) -> USB-C Laptop Charger | R64: =VLOOKUP(D64, 'Cleaned Product Dim Dataset'!$A:$G, 3, 0) -> Electronics | S64: =VLOOKUP(D64, 'Cleaned Product Dim Dataset'!$A:$G, 4, 0) -> Computer | T64: =VLOOKUP(D64, 'Cleaned Product Dim Dataset'!$A:$G, 5, 0) -> Martin LLC
A65: SALE63 | B65: 45927 | C65: CUST1126 | D65: PROD89 | E65: STORE12 | F65: 2 | G65: 121.37 | H65: 0.05 | I65: Credit Card | J65: 230.6 | K65: =VLOOKUP(C65,'Cleaned Customer_Dim'!$A$2:$H$501,4,0) -> Female | L65: =VLOOKUP(C65, 'Cleaned Customer_Dim'!$A:$F, 6, FALSE) -> Arizona | M65: =VLOOKUP(E65, 'Cleaned Stoer_ Dim'!$A$1:$E$21, 2, 0) -> Thomas, Bridges and Harris | N65: =VLOOKUP(E65, 'Cleaned Stoer_ Dim'!$A:$E,3, 0) -> North | O65: =VLOOKUP(E65, 'Cleaned Stoer_ Dim'!$A:$E, 4, 0) -> Sabrinatown | P65: =VLOOKUP(E65, 'Cleaned Stoer_ Dim'!$A:$E, 5, 0) -> Online | Q65: =VLOOKUP(D65, 'Cleaned Product Dim Dataset'!$A:$G, 2, 0) -> Face Foundation Kit | R65: =VLOOKUP(D65, 'Cleaned Product Dim Dataset'!$A:$G, 3, 0) -> Beauty | S65: =VLOOKUP(D65, 'Cleaned Product Dim Dataset'!$A:$G, 4, 0) -> Makeup | T65: =VLOOKUP(D65, 'Cleaned Product Dim Dataset'!$A:$G, 5, 0) -> Taylor-Elliott
...

Sheet Standard Deviation of Sales
A1: Sales
A3: Mean | B3: 1087.2
A4: Standard Error | B4: 0.77291667
A5: Median | B5: 868.98
A6: Mode | B6: 502.11
A7: Standard Deviation | B7: 819.41
A8: Minimum | B8: 18.46
A9: Maximum | B9: 3908.24
A10: Sum | B10: 2175481.7
A11: Count | B11: 2001

Sheet Pivot Chart
A3: Row Labels | B3: Sum of Total_Amount
A4: Female | B4: 1231444.2
A5: COD | B5: 410598.5
A6: Credit Card | B6: 373304.42
A7: PayPal | B7: 447541.26
A8: Male | B8: 942950.33
A9: COD | B9: 291860.78
A10: Credit Card | B10: 341876.22
A11: PayPal | B11: 309213.33
A12: Grand Total | B12: 2174394.5
A24: Count of Unit_Price | B24: Column Labels
B25: 2023 | C25: 2024 | D25: 2025 | E25: Grand Total
A28: Row Labels
A29: Beauty | B29: 33 | C29: 158 | D29: 113 | E29: 304
A30: Clothing | B30: 37 | C30: 181 | D30: 116 | E30: 334
A31: Electronics | B31: 49 | C31: 199 | D31: 206 | E31: 454
A32: Home | B32: 49 | C32: 203 | D32: 158 | E32: 410
A33: Sports | B33: 49 | C33: 258 | D33: 191 | E33: 498
A34: Grand Total | B34: 217 | C34: 999 | D34: 784 | E34: 2000
A47: Row Labels | B47: Sum of Total_Amount
A48: Flagship | B48: 848576.65
A49: Bensonhaven | B49: 122176.52
A50: Danielmouth | B50: 101060.64
A51: East Jenniferstad | B51: 99679.06
A52: East Johnstad | B52: 110102.44
A53: East Stevechester | B53: 104313.05
A54: Johnsonville | B54: 114401.46
A55: New Jimmymouth | B55: 111704.93
A56: Washingtonfurt | B56: 85138.55
A57: Online | B57: 914253.45
A58: East Davidville | B58: 109791.72
A59: Lake Michael | B59: 93048.13
... A71: Grand Total | B71: 2174394.5

Sheet Slicer Dashboard
A3: Row Labels | B3: Sum of Total_Amount
A4: Female | B4: 1231444.2
A5: COD | B5: 410598.5
A6: Credit Card | B6: 373304.42
A7: PayPal | B7: 447541.26
A8: Male | B8: 942950.33
A9: COD | B9: 291860.78
A10: Credit Card | B10: 341876.22
A11: PayPal | B11: 309213.33
A12: Grand Total | B12: 2174394.5
A24: Count of Unit_Price | B24: Column Labels
B25: 2023 | C25: 2024 | D25: 2025 | E25: Grand Total
A28: Row Labels
A29: Beauty | B29: 33 | C29: 158 | D29: 113 | E29: 304
A30: Clothing | B30: 37 | C30: 181 | D30: 116 | E30: 334
A31: Electronics | B31: 49 | C31: 199 | D31: 206 | E31: 454
A32: Home | B32: 49 | C32: 203 | D32: 158 | E32: 410
A33: Sports | B33: 49 | C33: 258 | D33: 191 | E33: 498
A34: Grand Total | B34: 217 | C34: 999 | D34: 784 | E34: 2000
A47: Row Labels | B47: Sum of Total_Amount
A48: Flagship | B48: 848576.65
A49: Bensonhaven | B49: 122176.52
A50: Danielmouth | B50: 101060.64
A51: East Jenniferstad | B51: 99679.06
A52: East Johnstad | B52: 110102.44
A53: East Stevechester | B53: 104313.05
A54: Johnsonville | B54: 114401.46
A55: New Jimmymouth | B55: 111704.93
A56: Washingtonfurt | B56: 85138.55
A57: Online | B57: 914253.45
A58: East Davidville | B58: 109791.72
A59: Lake Michael | B59: 93048.13
... A71: Grand Total | B71: 2174394.5
